Workbook

Sheet Parameters
A1: Parameters
A2: Probabilità | B2: - | D2: La probabilità è stata generata con la formula =CASUALE() direttamente all'interno della formula =INV.NORM.N
A3: Media | B3: 45
A4: Deviazione Standard | B4: 3.85

Sheet Data
A1: Età | B1: Gruppo
A2: 32.341348 | B2: 3
A3: 40.089538 | B3: 3 | D3: L'età del DataSet è stata creata casualmente utilizzando la seguente formula: '=INV.NORM.N(CASUALE();Parameters!$B$3;Parameters!$B$4). L'età della popolazione poi è stata copiata e incollata per evitare che i valori cambiassero continuamente. Il gruppo compreso tra 1 e 4 è stato calcolato, anche questo casualmente, con la funzione '=CASUALE.TRA(1;4) e come prima è stato copiato e incollato per evitare la modifica costante del valore del gruppo.
A4: 37.734315 | B4: 3
A5: 48.954328 | B5: 4
A6: 42.175914 | B6: 4
A7: 44.054542 | B7: 3
A8: 48.633313 | B8: 4
A9: 46.469211 | B9: 2
A10: 47.904616 | B10: 4
A11: 38.680651 | B11: 3
A12: 45.950753 | B12: 1
A13: 40.064491 | B13: 2
A14: 45.374397 | B14: 4
A15: 46.770353 | B15: 4
... A251: 38.581717 | B251: 4

Sheet Sample
A1: Età | B1: Gruppo | C1: Sotto campione | D1: Gruppo appartenenza
A2: =Data!A2 -> 32.341348 | B2: =Data!B2 -> 3 | C2: =IF(B2=$D$2,A2,"") -> 32.341348 | D2: 3
A3: =Data!A3 -> 40.089538 | B3: =Data!B3 -> 3 | C3: =IF(B3=$D$2,A3,"") -> 40.089538
A4: =Data!A4 -> 37.734315 | B4: =Data!B4 -> 3 | C4: =IF(B4=$D$2,A4,"") -> 37.734315
A5: =Data!A5 -> 48.954328 | B5: =Data!B5 -> 4 | C5: =IF(B5=$D$2,A5,"")
A6: =Data!A6 -> 42.175914 | B6: =Data!B6 -> 4 | C6: =IF(B6=$D$2,A6,"")
A7: =Data!A7 -> 44.054542 | B7: =Data!B7 -> 3 | C7: =IF(B7=$D$2,A7,"") -> 44.054542
A8: =Data!A8 -> 48.633313 | B8: =Data!B8 -> 4 | C8: =IF(B8=$D$2,A8,"")
A9: =Data!A9 -> 46.469211 | B9: =Data!B9 -> 2 | C9: =IF(B9=$D$2,A9,"")
A10: =Data!A10 -> 47.904616 | B10: =Data!B10 -> 4 | C10: =IF(B10=$D$2,A10,"")
A11: =Data!A11 -> 38.680651 | B11: =Data!B11 -> 3 | C11: =IF(B11=$D$2,A11,"") -> 38.680651
A12: =Data!A12 -> 45.950753 | B12: =Data!B12 -> 1 | C12: =IF(B12=$D$2,A12,"")
A13: =Data!A13 -> 40.064491 | B13: =Data!B13 -> 2 | C13: =IF(B13=$D$2,A13,"")
A14: =Data!A14 -> 45.374397 | B14: =Data!B14 -> 4 | C14: =IF(B14=$D$2,A14,"")
... A251: =Data!A251 -> 38.581717 | B251: =Data!B251 -> 4 | C251: =IF(B251=$D$2,A251,"")

Sheet Statistical Insight
A1: Varianza Nota | B1: Valori
A2: STDDEV Campione | B2: =_xlfn.STDEV.S(Sample!C2:C251) -> 4.0628768 | D2: STDDEV: è la deviazione standard del campione, stima della variabilità del campione di 4,06
A3: COUNT | B3: =COUNT(Sample!C2:C251) -> 54 | D3: COUNT: è la numerosità campionaria del sotto campione scelto del tab Sample. La quantità di 54 ci permette di utilizzare i dati ai fini dell'inferenza statistica.
A4: Expected Value (S) | B4: =AVERAGE(Sample!C2:C251) -> 44.115488 | D4: Expected Value (S) età media del campione, che è vicino all'età media della popolazione.
A5: Varianza Popolazione | B5: =_xlfn.VAR.P(Sample!A2:A251) -> 14.681921 | D5: Varianza Popolazione: è la varianza della Popolazione, ha una dispersione intorno la media di 14,68
A6: STDDEV Popolazione | B6: =SQRT(B5) -> 3.8316995 | C6: =_xlfn.STDEV.P(Sample!A2:A251) -> 3.8316995 | D6: STDDEV: è la deviazione standard della popolazione, stima leggermente più bassa rispetto dalla STDDEV Campionaria
A7: Standard error | B7: =B6/SQRT(B3) -> 0.52142825 | D7: Standard error: variabilità della stima del campione, 0,52
A8: Media popolazione | B8: =AVERAGE(Sample!A2:A251) -> 44.818944
A9: Confidenza | B9: 0.95 | D9: In base al calcolo appena effettuato possiamo affermare con una confidenza del 95% che l'età della popolazione varia da un valore minimo di 43,09 a una massimo di 45,14. Il campione preso in considerazione di 54 valori.
A10: Alfa | B10: 0.05
A11: Z | B11: =_xlfn.NORM.S.INV(1-B10/2) -> 1.959964
A12: Limite inferiore | B12: =B4-B11*B7 -> 43.093508
A13: Limite superiore | B13: =B4+B11*B7 -> 45.137469 | D13: Estimation of P Parameter: Il Test Z riporta un valore uguale 0,18 che è maggiore di 0,05. L'ipotesi quindi viene accettata in quando il valore non implica una differenza significativa tra le medie e quindi non c'è sufficiente evidenza per rifiutare l'ipotesi nulla.
A14: Estimation of P Parameter | B14: =2*MIN(_xlfn.Z.TEST(Sample!C2:C251,B8,B6),1-_xlfn.Z.TEST(Sample!C2:C251,B8,B6)) -> 0.17730718

Sheet (Un)correlated Variables
A1: Sample data | B1: Number of cats | C1: Age of partner
A2: 32.341348 | B2: 0 | C2: 43.012679 | E2: Covarianza Gatto | F2: =_xlfn.COVARIANCE.S(A2:A55,B2:B55) -> 0.8913252 | G2: La correlazione tra Età della persona e gatti posseduto è 0,15, molto vicino allo zero. Questo ci indica una correlazione debole tra età e gatti posseduti. Non c'è una relazione lineare significativa.
A3: 40.089538 | B3: 0 | C3: 45.408294 | E3: Correlazione Età - Gatto | F3: =PEARSON(A2:A55,B2:B55) -> 0.15233174
A4: 37.734315 | B4: 1 | C4: 44.84487 | E4: T test | F4: =_xlfn.T.TEST(A2:A55,B2:B55,2,1) -> 1.1808842e-55
A5: 44.054542 | B5: 2 | C5: 46.983108
A6: 38.680651 | B6: 2 | C6: 41.355816
A7: 39.013691 | B7: 0 | C7: 43.830444
A8: 48.188231 | B8: 1 | C8: 49.475766
A9: 39.084448 | B9: 4 | C9: 45.341671
A10: 42.704712 | B10: 3 | C10: 48.173973
A11: 44.929975 | B11: 2 | C11: 37.208782
A12: 40.630407 | B12: 4 | C12: 36.534981
A13: 51.211577 | B13: 3 | C13: 49.151389
A14: 51.475041 | B14: 1 | C14: 45.443341
A15: 45.720476 | B15: 4 | C15: 34.341559
A16: 37.144583 | B16: 0 | C16: 38.648393
... A21: 48.182708 | B21: 0 | C21: 40.388209
A22: 42.060672 | B22: 3 | C22: 47.043141 | E22: Covarianza età partner | F22: =_xlfn.COVARIANCE.S(A2:A55,C2:C55) -> 3.6088287 | G22: La correlazione tra l'età dei partner è tendende allo zero, 0,23. Questo suggerisce una correlazione debole. La relazione lineare non è significativa.
A23: 43.345625 | B23: 4 | C23: 45.890223 | E23: Correlazione Età - Partner età | F23: =PEARSON(A2:A55,C2:C55) -> 0.22773353
A24: 43.042394 | B24: 2 | C24: 42.989853 | E24: T test | F24: =_xlfn.T.TEST(A2:A55,C2:C55,2,1) -> 0.88572967
A25: 36.000402 | B25: 1 | C25: 40.694848
A26: 38.437682 | B26: 3 | C26: 46.457747
A27: 41.647458 | B27: 2 | C27: 39.01849
A28: 42.051684 | B28: 2 | C28: 35.196169
A29: 44.766224 | B29: 0 | C29: 43.30345
A30: 46.49791 | B30: 0 | C30: 40.409438
A31: 41.94114 | B31: 0 | C31: 49.402167
A32: 43.486966 | B32: 3 | C32: 43.439555
A33: 49.461986 | B33: 4 | C33: 44.040131
A34: 39.767203 | B34: 1 | C34: 47.701936
A35: 42.914644 | B35: 3 | C35: 45.852829
A36: 44.209557 | B36: 1 | C36: 44.738695
... A41: 49.414125 | B41: 3 | C41: 49.403219
A42: 46.875531 | B42: 4 | C42: 43.525568 | E42: Anche in questo caso abbiamo utilizzare la formula '=CASUALE.TRA(0;4) per calcolare quanti gatti possiede una persona e la formula'=INV.NORM.N(CASUALE();Parameters!$B$3;Parameters!$B$4) per calcolare l'età dei partner. Entrambi sono stati copiati e incollati i soli valori per non essere continuamente modificati.
A43: 47.989197 | B43: 0 | C43: 48.940434
A44: 44.331878 | B44: 3 | C44: 41.496707
A45: 43.245156 | B45: 3 | C45: 45.973378
A46: 47.725229 | B46: 1 | C46: 42.005563
A47: 45.283528 | B47: 2 | C47: 47.280865
A48: 48.51622 | B48: 1 | C48: 42.254182
...

Sheet Linear regression
A1: Age (Y) | B1: Rank(X)
A2: =Data!A2 -> 32.341348 | B2: 1 | D2: Previsione lineare | E2: =_xlfn.FORECAST.LINEAR(160,A2:A251,B2:B251) -> 44.975323
A3: =Data!A3 -> 40.089538 | B3: 2
A4: =Data!A4 -> 37.734315 | B4: 3
A5: =Data!A5 -> 48.954328 | B5: 4
A6: =Data!A6 -> 42.175914 | B6: 5
A7: =Data!A7 -> 44.054542 | B7: 6
A8: =Data!A8 -> 48.633313 | B8: 7
A9: =Data!A9 -> 46.469211 | B9: 8
A10: =Data!A10 -> 47.904616 | B10: 9
A11: =Data!A11 -> 38.680651 | B11: 10
A12: =Data!A12 -> 45.950753 | B12: 11
A13: =Data!A13 -> 40.064491 | B13: 12
A14: =Data!A14 -> 45.374397 | B14: 13
... A251: =Data!A251 -> 38.581717 | B251: 250
